<?xml version="1.0"?>
<sdf version="1.7">
  <model name="acrobot">
    <!-- This sdf file produces a model with the default parameters documented
         in AcrobotParameters in make_acrobot_plant.h.
         They MUST be kept in sync. -->
    <link name="Link1">
      <!-- The origin of the Link1 frame is defined to be coincident with
           the origin of the x-z plane in the world frame. -->
      <pose>0 0 0 0 0 0</pose>
      <inertial>
        <pose>0.5 0 0 0 0 0</pose>
        <mass>1</mass>
        <!-- This inertia is based on a solid cylinder with
             radius=0.001 meters and height=1.0 meters. -->
        <!-- For this model we could make izz = 0 however, sdformat will throw
             an exception. -->
        <inertia>
          <ixx>5e-7</ixx>
          <iyy>0.083</iyy>
          <izz>0.083</izz>
          <ixy>0</ixy>
          <ixz>0</ixz>
          <iyz>0</iyz>
        </inertia>
      </inertial>
      <visual name="Link1_visual">
        <pose>0.5 0 0 0 1.5708 0</pose>
        <geometry>
          <cylinder>
            <length>1.0</length>
            <radius>0.05</radius>
          </cylinder>
        </geometry>
        <material>
          <diffuse>0 1 0 1</diffuse>
        </material>
      </visual>
      <!-- A visual to show the link's pivot point -->
      <visual name="Link1_pivot_visual">
        <!-- Pose of the sphere used for visual in Link1's frame -->
        <geometry>
          <sphere>
            <radius>0.125</radius>
          </sphere>
        </geometry>
        <material>
          <diffuse>0 0 1 1</diffuse>
        </material>
      </visual>
    </link>
    <joint name="ShoulderJoint" type="revolute">
      <child>Link1</child>
      <parent>world</parent>
      <axis>
        <xyz expressed_in="__model__">0 0 1</xyz>
        <limit>
          <!-- Drake parses a zero effort joint as an un-actuated joint. -->
          <!-- <effort>0</effort> -->
        </limit>
        <dynamics>
          <damping>1.1</damping>
        </dynamics>
      </axis>
    </joint>
    <frame name="end_effector" attached_to="Link1">
      <!-- The pose of the end_effector frame relative to the Link1 frame -->
      <!-- Assuming the length of Link1 is 1.0, the end effector is at the end of the link -->
      <pose>1 0 0 0 0 0</pose>
    </frame>
  </model>
</sdf>
